Workbook

Sheet ReadMe
A1: (last update: 10/08/2026)
A2: M. Arias-Osorio, R. Moshrif, G. Nievas, T. Piketty, A. Van Der Ree "Global Inequality Update 2026: Insights from the WID Macro Series", WIL TN, 2026
A4: Content
A5: Tables
A6: 1 | B6: ='T1'!A1 -> Table 1. Gross domestic product by World Region USD-EUR (2025)
A7: 2 | B7: =T1a!A1 -> Table 1a. Per capita gross domestic product by World Region USD-EUR (2025)
A8: 3 | B8: ='T2'!A1 -> Table 2. Consumption of Fixed Capital by World Region USD-EUR (2025)
A9: 4 | B9: ='T3'!A1 -> Table 3. National Income by World Region USD-EUR (2025)
A10: 5 | B10: ='T4'!A1 -> Table 4. Per Capita National Income by World Region (2025)
A11: 6 | B11: =T4a!A1 -> Table 4a. Per capita national Income by World Region USD-EUR (2025)
B12: =DataT3c!B3 -> Table 3c. National Income by World Region (2021): New PPP (ICP 2021) vs Old PPP (ICP 2011)
A13: 7 | B13: =T5a!A1 -> Table 5a. Per Capita National Income Growth PPP 2025 € by World Regions (1800-2025)
A14: 8 | B14: =T5b!A1 -> Table 5b. Per Capita National Income Growth PPP 2025 $ by World Regions (1800-2025)
A15: 9 | B15: =T5c!A1 -> Table 5c. Per Capita National Income Growth MER 2025 € by World Regions (1800-2025)
A16: 10 | B16: =T5d!A1 -> Table 5d. Per Capita National Income Growth MER 2025 $ by World Regions (1800-2025)
A17: 11 | B17: ='T6'!A1 -> Table 6. Per Capita National Income Growth PPP 2025 € by WID core Territories (1980-2025)
A18: 12 | B18: ='T7'!A1 -> Table 7. Population by World Regions (1800-2025)
A19: 13 | B19: =T8a!A1 -> Table 8a. Price index Growth PPP 2025 € by World Regions (1980-2025)
A20: 14 | B20: =T8b!A1 -> Table 8b. Price index Growth PPP 2025 $ by World Regions (1980-2025)
A21: 15 | B21: =T8c!A1 -> Table 8c. Price index Growth MER € by World Regions (1980-2025)
A22: 16 | B22: =T8d!A1 -> Table 8d. Price index Growth MER $ by World Regions (1980-2025)
A23: 17 | B23: ='T9'!A1 -> Table 9. Price index Growth € by Core countries (1980-2025)
A24: 18 | B24: =T10a!A1 -> Table10a. Top 10 Richest Countries (2025),including countries with population below 10 million
A25: 19 | B25: =T10b!A1 -> Table10b. Top 10 Richest Countries (2025), excluding countries with population below 10 million
A26: 20 | B26: ='T11'!A1 -> Table 11. Bottom 10 Poorest Countries (2025)
A27: 21 | B27: ='T12'!A1 -> Table 12. Top 10 Largest Economies (2025)
A28: 22 | B28: =T13a!A1 -> Table 13a. Current Account by World Region PPP € (2025)
A29: 23 | B29: =T13b!A1 -> Table 13b. Current Account by World Region PPP $ (2025)
A30: 24 | B30: =T13c!A1 -> Table 13c. Current Account by World Region MER € (2025)
A31: 25 | B31: =T13d!A1 -> Table 13d. Current Account by World Region MER $ (2025)
A32: 26 | B32: =T14a!A1 -> Table 14a. Net foreign Assets PPP € 2025 by World Regions (1980-2025)
A33: 27 | B33: =T14b!A1 -> Table 14d. Net foreign Assets MER$ by World Regions (1980-2025)
A34: 28 | B34: =T14c!A1 -> Table 14c. Net foreign Assets MER € by World Regions (1980-2025)
A35: 29 | B35: =T14d!A1 -> Table 14d. Net foreign Assets MER$ by World Regions (1980-2025)
A36: 30 | B36: =T15a!A1 -> Table 15a. National Non-financial Assets by World Region PPP € (2025)
A37: 31 | B37: =T15b!A1 -> Table 15b. National Non-financial Assets by World Region PPP $ (2025)
A38: 32 | B38: =T15c!A1 -> Table 15c. National Non-financial Assets by World Region MER € (2025)
A39: 33 | B39: =T15d!A1 -> Table 15d. National Non-financial Assets by World Region MER $ (2025)
A40: 34 | B40: =T16a!A1 -> Table 16a. National Capital shares by World Region PPP € (2025)
A41: 35 | B41: =T16b!A1 -> Table 16b. National Capital shares by World Region PPP $ (2025)
...

Sheet F0a

Sheet F0b

Sheet T1
A1: =DataT1!B2 -> Table 1. Gross domestic product by World Region USD-EUR (2025)
B2: =DataT1!C3 -> PPP 2025 billions € | D2: =DataT1!E3 -> 2025 MER billions € | F2: =DataT1!G3 -> PPP 2025 billions $ | H2: =DataT1!I3 -> 2025 MER billions $
B3: =DataT1!C4 -> Gross domestic product | C3: =DataT1!D4 -> Gross domestic product (% world total) | D3: =DataT1!E4 -> Gross domestic product | E3: =DataT1!F4 -> Gross domestic product (% world total) | F3: =DataT1!G4 -> Gross domestic product | G3: =DataT1!H4 -> Gross domestic product (% world total) | H3: =DataT1!I4 -> Gross domestic product | I3: =DataT1!J4 -> Gross domestic product (% world total)
A4: =DataT1!B5 -> East Asia | B4: =DataT1!C5 -> 37298.113 | C4: =DataT1!D5/100 -> 0.26015704 | D4: =DataT1!E5 -> 23215.605 | E4: =DataT1!F5/100 -> 0.22605071 | F4: =DataT1!G5 -> 55011.574 | G4: =DataT1!H5/100 -> 0.26015705 | H4: =DataT1!I5 -> 27362.758 | I4: =DataT1!J5/100 -> 0.22605072
A5: =DataT1!B6 -> Europe | B5: =DataT1!C6 -> 24116.732 | C5: =DataT1!D6/100 -> 0.16821595 | D5: =DataT1!E6 -> 23800.626 | E5: =DataT1!F6/100 -> 0.23174707 | F5: =DataT1!G6 -> 35570.144 | G5: =DataT1!H6/100 -> 0.16821594 | H5: =DataT1!I6 -> 28052.286 | I5: =DataT1!J6/100 -> 0.23174709
A6: =DataT1!B7 -> Latin America | B6: =DataT1!C7 -> 10322.067 | C6: =DataT1!D7/100 -> 0.071997169 | D6: =DataT1!E7 -> 6496.2763 | E6: =DataT1!F7/100 -> 0.063254344 | F6: =DataT1!G7 -> 15224.179 | G6: =DataT1!H7/100 -> 0.071997166 | H6: =DataT1!I7 -> 7656.7479 | I6: =DataT1!J7/100 -> 0.063254346
A7: =DataT1!B8 -> MENA | B7: =DataT1!C8 -> 10670.033 | C7: =DataT1!D8/100 -> 0.074424253 | D7: =DataT1!E8 -> 5608.5037 | E7: =DataT1!F8/100 -> 0.054610088 | F7: =DataT1!G8 -> 15737.399 | G7: =DataT1!H8/100 -> 0.074424253 | H7: =DataT1!I8 -> 6610.3872 | I7: =DataT1!J8/100 -> 0.054610094
A8: =DataT1!B9 -> North America & Oceania | B8: =DataT1!C9 -> 24436.488 | C8: =DataT1!D9/100 -> 0.17044628 | D8: =DataT1!E9 -> 30016.639 | E8: =DataT1!F9/100 -> 0.29227249 | F8: =DataT1!G9 -> 36041.76 | G8: =DataT1!H9/100 -> 0.17044628 | H8: =DataT1!I9 -> 35378.704 | I8: =DataT1!J9/100 -> 0.29227249
A9: =DataT1!B10 -> Russia & Central Asia | B9: =DataT1!C10 -> 7011.3215 | C9: =DataT1!D10/100 -> 0.048904475 | D9: =DataT1!E10 -> 3149.6041 | E9: =DataT1!F10/100 -> 0.030667745 | F9: =DataT1!G10 -> 10341.108 | G9: =DataT1!H10/100 -> 0.048904474 | H9: =DataT1!I10 -> 3712.2382 | I9: =DataT1!J10/100 -> 0.030667746
A10: =DataT1!B11 -> South & South-East Asia | B10: =DataT1!C11 -> 23742.554 | C10: =DataT1!D11/100 -> 0.16560603 | D10: =DataT1!E11 -> 8057.2831 | E10: =DataT1!F11/100 -> 0.078453892 | F10: =DataT1!G11 -> 35018.265 | G10: =DataT1!H11/100 -> 0.16560603 | H10: =DataT1!I11 -> 9496.6075 | I10: =DataT1!J11/100 -> 0.078453896
A11: =DataT1!B12 -> Sub-Saharan Africa | B11: =DataT1!C12 -> 5298.7413 | C11: =DataT1!D12/100 -> 0.036959104 | D11: =DataT1!E12 -> 2356.3311 | E11: =DataT1!F12/100 -> 0.022943633 | F11: =DataT1!G12 -> 7815.1966 | G11: =DataT1!H12/100 -> 0.036959104 | H11: =DataT1!I12 -> 2777.2578 | I11: =DataT1!J12/100 -> 0.022943635
A12: =DataT1!B13 -> World | B12: =DataT1!C13 -> 143367.69 | C12: =DataT1!D13/100 -> 1 | D12: =DataT1!E13 -> 102700.87 | E12: =DataT1!F13/100 -> 1 | F12: =DataT1!G13 -> 211455.25 | G12: =DataT1!H13/100 -> 1 | H12: =DataT1!I13 -> 121046.98 | I12: =DataT1!J13/100 -> 1
A13: Interpretation. In 2025, gross domestic product amounts to 143 368€ (PPP) billion worldwide. Gross domestic product, varies from little more than 5 299€ billion in Subsaharan Africa to almost 24 436€ billion in North America/Oceania , i.e., an income scale of 1 to 5. Sources and series: wid.world

Sheet T1a
A1: =DataT1a!B2 -> Table 1a. Per capita gross domestic product by World Region USD-EUR (2025)
B2: =DataT1a!C3 -> PPP 2025 € | D2: =DataT1a!E3 -> 2025 MER € | F2: =DataT1a!G3 -> PPP 2025 $ | H2: =DataT1a!I3 -> 2025 MER $
B3: =DataT1a!C4 -> Per capita gross domestic product | C3: =DataT1a!D4 -> Per capita gross domestic product (% world total) | D3: =DataT1a!E4 -> Per capita gross domestic product | E3: =DataT1a!F4 -> Per capita gross domestic product (% world total) | F3: =DataT1a!G4 -> Per capita gross domestic product | G3: =DataT1a!H4 -> Per capita gross domestic product (% world total) | H3: =DataT1a!I4 -> Per capita gross domestic product | I3: =DataT1a!J4 -> Per capita gross domestic product (% world total)
A4: =DataT1a!B5 -> East Asia | B4: =DataT1a!C5 -> 22575.014 | C4: =DataT1a!D5/100 -> 1.2959992 | D4: =DataT1a!E5 -> 14051.451 | E4: =DataT1a!F5/100 -> 1.126095 | F4: =DataT1a!G5 -> 33296.243 | G4: =DataT1a!H5/100 -> 1.2959992 | H4: =DataT1a!I5 -> 16561.552 | I4: =DataT1a!J5/100 -> 1.126095
A5: =DataT1a!B6 -> Europe | B5: =DataT1a!C6 -> 43376.585 | C5: =DataT1a!D6/100 -> 2.4901876 | D5: =DataT1a!E6 -> 42808.035 | E5: =DataT1a!F6/100 -> 3.4306716 | F5: =DataT1a!G6 -> 63976.804 | G5: =DataT1a!H6/100 -> 2.4901875 | H5: =DataT1a!I6 -> 50455.111 | I5: =DataT1a!J6/100 -> 3.4306719
A6: =DataT1a!B7 -> Latin America | B6: =DataT1a!C7 -> 15481.475 | C6: =DataT1a!D7/100 -> 0.88876931 | D6: =DataT1a!E7 -> 9743.391 | E6: =DataT1a!F7/100 -> 0.78084347 | F6: =DataT1a!G7 -> 22833.869 | G6: =DataT1a!H7/100 -> 0.88876927 | H6: =DataT1a!I7 -> 11483.916 | I6: =DataT1a!J7/100 -> 0.7808435
A7: =DataT1a!B8 -> MENA | B7: =DataT1a!C8 -> 17428.241 | C7: =DataT1a!D8/100 -> 1.0005303 | D7: =DataT1a!E8 -> 9160.8296 | E7: =DataT1a!F8/100 -> 0.73415651 | F7: =DataT1a!G8 -> 25705.186 | G7: =DataT1a!H8/100 -> 1.0005303 | H7: =DataT1a!I8 -> 10797.288 | I7: =DataT1a!J8/100 -> 0.73415659
A8: =DataT1a!B9 -> North America & Oceania | B8: =DataT1a!C9 -> 56325.387 | C8: =DataT1a!D9/100 -> 3.2335598 | D8: =DataT1a!E9 -> 69187.47 | E8: =DataT1a!F9/100 -> 5.5447415 | F8: =DataT1a!G9 -> 83075.197 | G8: =DataT1a!H9/100 -> 3.2335598 | H8: =DataT1a!I9 -> 81546.871 | I8: =DataT1a!J9/100 -> 5.5447416
A9: =DataT1a!B10 -> Russia & Central Asia | B9: =DataT1a!C10 -> 23951.503 | C9: =DataT1a!D10/100 -> 1.3750215 | D9: =DataT1a!E10 -> 10759.42 | E9: =DataT1a!F10/100 -> 0.86226888 | F9: =DataT1a!G10 -> 35326.446 | G9: =DataT1a!H10/100 -> 1.3750214 | H9: =DataT1a!I10 -> 12681.445 | I9: =DataT1a!J10/100 -> 0.86226893
A10: =DataT1a!B11 -> South & South-East Asia | B10: =DataT1a!C11 -> 8816.9793 | C10: =DataT1a!D11/100 -> 0.50617015 | D10: =DataT1a!E11 -> 2992.1339 | E10: =DataT1a!F11/100 -> 0.2397921 | F10: =DataT1a!G11 -> 13004.301 | G10: =DataT1a!H11/100 -> 0.50617016 | H10: =DataT1a!I11 -> 3526.638 | I10: =DataT1a!J11/100 -> 0.23979212 | K10: =B8/B11 -> 14.074092
A11: =DataT1a!B12 -> Sub-Saharan Africa | B11: =DataT1a!C12 -> 4002.0618 | C11: =DataT1a!D12/100 -> 0.22975263 | D11: =DataT1a!E12 -> 1779.7024 | E11: =DataT1a!F12/100 -> 0.14262684 | F11: =DataT1a!G12 -> 5902.7037 | G11: =DataT1a!H12/100 -> 0.22975264 | H11: =DataT1a!I12 -> 2097.6222 | I11: =DataT1a!J12/100 -> 0.14262685
A12: =DataT1a!B13 -> World | B12: =DataT1a!C13 -> 17419.003 | C12: =DataT1a!D13/100 -> 1 | D12: =DataT1a!E13 -> 12478.033 | E12: =DataT1a!F13/100 -> 1 | F12: =DataT1a!G13 -> 25691.561 | G12: =DataT1a!H13/100 -> 1 | H12: =DataT1a!I13 -> 14707.064 | I12: =DataT1a!J13/100 -> 1
A13: Interpretation. In 2025, per capita gross domestic product amounts to 17 419€ (PPP) worldwide, i.e., 1 452€ per month. Per capita gross domestic product, i.e., the part of the product which all individuals would receive with a perfectly egalitarian distribution, varies from an average of little more than 4 002€ in Subsaharan Africa (about 333€ per month) to over 56 325€ in North America/Oceania (about 4 693€ per month), i.e., an income scale of 1 to 14. Sources and series: wid.world

Sheet T2
A1: =DataT2!B2 -> Table 2. Consumption of Fixed Capital by World Region USD-EUR (2025)
B2: =DataT2!C3 -> PPP 2025 billions € | E2: =DataT2!F3 -> 2025 MER billions € | H2: =DataT2!I3 -> PPP 2025 billions $ | K2: =DataT2!L3 -> 2025 MER billions $
B3: =DataT2!C4 -> Consumption of Fixed Capital | C3: =DataT2!D4 -> Consumption of Fixed Capital (% regional GDP) | D3: =DataT2!E4 -> Consumption of Fixed Capital (% world Consumption of Fixed capital total) | E3: =DataT2!F4 -> Consumption of Fixed Capital | F3: =DataT2!G4 -> Consumption of Fixed Capital (% regional GDP) | G3: =DataT2!H4 -> Consumption of Fixed Capital (% world Consumption of Fixed capital total) | H3: =DataT2!I4 -> Consumption of Fixed Capital | I3: =DataT2!J4 -> Consumption of Fixed Capital (% regional GDP) | ... M3: =DataT2!N4 -> Consumption of Fixed Capital (% world Consumption of Fixed capital total)
A4: =DataT2!B5 -> East Asia | B4: =DataT2!C5 -> 7030.8739 | C4: =DataT2!D5 -> 0.18850481 | D4: =DataT2!E5 -> 0.32014003 | E4: =DataT2!F5 -> 4453.0428 | F4: =DataT2!G5 -> 0.19181248 | G4: =DataT2!H5 -> 0.26679831 | H4: =DataT2!I5 -> 10369.947 | ... M4: =DataT2!N5 -> 0.2667983
A5: =DataT2!B6 -> Europe | B5: =DataT2!C6 -> 4134.191 | C5: =DataT2!D6 -> 0.17142418 | D5: =DataT2!E6 -> 0.18824403 | E5: =DataT2!F6 -> 4127.6796 | F5: =DataT2!G6 -> 0.17342735 | G5: =DataT2!H6 -> 0.2473046 | H5: =DataT2!I6 -> 6097.583 | ... M5: =DataT2!N6 -> 0.24730459
A6: =DataT2!B7 -> Latin America | B6: =DataT2!C7 -> 1322.6018 | C6: =DataT2!D7 -> 0.12813341 | D6: =DataT2!E7 -> 0.060222636 | E6: =DataT2!F7 -> 842.22538 | F6: =DataT2!G7 -> 0.12964741 | G6: =DataT2!H7 -> 0.050460847 | H6: =DataT2!I7 -> 1950.726 | ... M6: =DataT2!N7 -> 0.050460846
A7: =DataT2!B8 -> MENA | B7: =DataT2!C8 -> 1172.9157 | C7: =DataT2!D8 -> 0.10992616 | D7: =DataT2!E8 -> 0.053406913 | E7: =DataT2!F8 -> 645.51663 | F7: =DataT2!G8 -> 0.11509605 | G7: =DataT2!H8 -> 0.038675296 | H7: =DataT2!I8 -> 1729.9518 | ... M7: =DataT2!N8 -> 0.038675296
A8: =DataT2!B9 -> North America & Oceania | B8: =DataT2!C9 -> 4061.7377 | C8: =DataT2!D9 -> 0.16621609 | D8: =DataT2!E9 -> 0.18494498 | E8: =DataT2!F9 -> 4998.6314 | F8: =DataT2!G9 -> 0.16652868 | G8: =DataT2!H9 -> 0.29948655 | H8: =DataT2!I9 -> 5990.7205 | ... M8: =DataT2!N9 -> 0.29948654
A9: =DataT2!B10 -> Russia & Central Asia | B9: =DataT2!C10 -> 966.72875 | C9: =DataT2!D10 -> 0.1378811 | D9: =DataT2!E10 -> 0.044018507 | E9: =DataT2!F10 -> 431.07341 | F9: =DataT2!G10 -> 0.1368659 | G9: =DataT2!H10 -> 0.025827207 | H9: =DataT2!I10 -> 1425.8434 | ... M9: =DataT2!N10 -> 0.025827208
A10: =DataT2!B11 -> South & South-East Asia | B10: =DataT2!C11 -> 2755.6008 | C10: =DataT2!D11 -> 0.11606169 | D10: =DataT2!E11 -> 0.12547204 | E10: =DataT2!F11 -> 962.99039 | F10: =DataT2!G11 -> 0.119518 | G10: =DataT2!H11 -> 0.057696326 | H10: =DataT2!I11 -> 4064.2788 | ... M10: =DataT2!N11 -> 0.057696324
A11: =DataT2!B12 -> Sub-Saharan Africa | B11: =DataT2!C12 -> 517.22055 | C11: =DataT2!D12 -> 0.097611966 | D11: =DataT2!E12 -> 0.023550842 | E11: =DataT2!F12 -> 229.51139 | F11: =DataT2!G12 -> 0.097402013 | G11: =DataT2!H12 -> 0.013750879 | H11: =DataT2!I12 -> 762.8567 | ... M11: =DataT2!N12 -> 0.013750879
A12: =DataT2!B13 -> World | B12: =DataT2!C13 -> 21961.87 | C12: =DataT2!D13 -> 0.15369123 | D12: =DataT2!E13 -> 0.99999998 | E12: =DataT2!F13 -> 16690.671 | F12: =DataT2!G13 -> 0.16251733 | G12: =DataT2!H13 -> 1 | H12: =DataT2!I13 -> 32391.907 | ... M12: =DataT2!N13 -> 0.99999999
A13: Interpretation. In 2025, consumption of fixed capital amounts to €21,962 billion (2025 PPP) worldwide, equivalent to slightly more than 15% of global GDP. East Asia accounts for the largest share of global consumption of fixed capital, representing 32% in € and 27% in $, equivalent to approximately 19% of the region’s GDP. By contrast, Sub-Saharan Africa accounts for less than 2% of global consumption of fixed capital in both currencies, corresponding to approximately 10% of the region’s GDP. The relative position of regions varies depending on whether values are expressed using PPP or MER. For instance, Europe’s share of global consumption of fixed capital increases from 19% in PPP terms to 25% in MER terms. Similarly, North America and Oceania increase their share from 18% to 30% when moving from PPP to MER terms. This reflects, in part, the relatively strong currencies of these regions compared with those of other regions. Sources and series: wid.world

Sheet T3
A1: =DataT3!B2 -> Table 3. National Income by World Region USD-EUR (2025)
B2: =DataT3!C3 -> PPP 2025 billions € | D2: =DataT3!E3 -> 2025 MER billions € | F2: =DataT3!G3 -> PPP 2025 billions $ | H2: =DataT3!I3 -> 2025 MER billions $
B3: =DataT3!C4 -> National income | C3: =DataT3!D4 -> National income (% world total) | D3: =DataT3!E4 -> National income | E3: =DataT3!F4 -> National income (% world total) | F3: =DataT3!G4 -> National income | G3: =DataT3!H4 -> National income (% world total) | H3: =DataT3!I4 -> National income | I3: =DataT3!J4 -> National income (% world total)
A4: =DataT3!B5 -> East Asia | B4: =DataT3!C5 -> 30310.742 | C4: =DataT3!D5/100 -> 0.25244657 | D4: =DataT3!E5 -> 18893.618 | E4: =DataT3!F5/100 -> 0.2196672 | F4: =DataT3!G5 -> 44705.789 | G4: =DataT3!H5/100 -> 0.25244656 | H4: =DataT3!I5 -> 22268.707 | I4: =DataT3!J5/100 -> 0.2196672
A5: =DataT3!B6 -> Europe | B5: =DataT3!C6 -> 20201.059 | C5: =DataT3!D6/100 -> 0.16824689 | D5: =DataT3!E6 -> 19982.903 | E5: =DataT3!F6/100 -> 0.2323318 | F5: =DataT3!G6 -> 29794.859 | G5: =DataT3!H6/100 -> 0.16824688 | H5: =DataT3!I6 -> 23552.579 | I5: =DataT3!J6/100 -> 0.23233181
A6: =DataT3!B7 -> Latin America | B6: =DataT3!C7 -> 8669.1455 | C6: =DataT3!D7/100 -> 0.072201995 | D6: =DataT3!E7 -> 5460.5569 | E6: =DataT3!F7/100 -> 0.063487323 | F6: =DataT3!G7 -> 12786.258 | G6: =DataT3!H7/100 -> 0.072201991 | H6: =DataT3!I7 -> 6436.0114 | I6: =DataT3!J7/100 -> 0.063487322
A7: =DataT3!B8 -> MENA | B7: =DataT3!C8 -> 9423.3006 | C7: =DataT3!D8/100 -> 0.078483064 | D7: =DataT3!E8 -> 4949.6985 | E7: =DataT3!F8/100 -> 0.057547813 | F7: =DataT3!G8 -> 13898.574 | G7: =DataT3!H8/100 -> 0.078483061 | H7: =DataT3!I8 -> 5833.8953 | I7: =DataT3!J8/100 -> 0.057547814
A8: =DataT3!B9 -> North America & Oceania | B8: =DataT3!C9 -> 20396.536 | C8: =DataT3!D9/100 -> 0.16987494 | D8: =DataT3!E9 -> 25039.377 | E8: =DataT3!F9/100 -> 0.29112104 | F8: =DataT3!G9 -> 30083.169 | G8: =DataT3!H9/100 -> 0.16987493 | H8: =DataT3!I9 -> 29512.321 | I8: =DataT3!J9/100 -> 0.29112103
A9: =DataT3!B10 -> Russia & Central Asia | B9: =DataT3!C10 -> 5964.8477 | C9: =DataT3!D10/100 -> 0.049678934 | D9: =DataT3!E10 -> 2684.9708 | E9: =DataT3!F10/100 -> 0.031216891 | F9: =DataT3!G10 -> 8797.6471 | G9: =DataT3!H10/100 -> 0.04967893 | H9: =DataT3!I10 -> 3164.6047 | I9: =DataT3!J10/100 -> 0.031216892
A10: =DataT3!B11 -> South & South-East Asia | B10: =DataT3!C11 -> 20456.394 | C10: =DataT3!D11/100 -> 0.17037347 | D10: =DataT3!E11 -> 6950.256 | E10: =DataT3!F11/100 -> 0.080807352 | F10: =DataT3!G11 -> 30171.455 | G10: =DataT3!H11/100 -> 0.17037346 | H10: =DataT3!I11 -> 8191.825 | I10: =DataT3!J11/100 -> 0.08080735
A11: =DataT3!B12 -> Sub-Saharan Africa | B11: =DataT3!C12 -> 4645.9292 | C11: =DataT3!D12/100 -> 0.038694166 | D11: =DataT3!E12 -> 2048.8171 | E11: =DataT3!F12/100 -> 0.023820632 | F11: =DataT3!G12 -> 6852.354 | G11: =DataT3!H12/100 -> 0.038694166 | H11: =DataT3!I12 -> 2414.8106 | I11: =DataT3!J12/100 -> 0.023820632
A12: =DataT3!B13 -> World | B12: =DataT3!C13 -> 120067.95 | C12: =DataT3!D13/100 -> 1 | D12: =DataT3!E13 -> 86010.193 | E12: =DataT3!F13/100 -> 1 | F12: =DataT3!G13 -> 177090.11 | G12: =DataT3!H13/100 -> 1 | H12: =DataT3!I13 -> 101374.75 | I12: =DataT3!J13/100 -> 1
A13: Interpretation. In 2025, national income amounts to 120 068€ (PPP) billion worldwide. National Income, varies from an average of little more than 4 646 billion € in Subsaharan Africa to over 20 397 € billion in North America/Oceania , i.e., an income scale of 1 to 4. Sources and series: wid.world

Sheet T4
A1: ='DataT4-'!B3 -> Table 4. Per Capita National Income by World Region (2025)
B2: ='DataT4-'!C4 -> Population (millions) | C2: ='DataT4-'!D4 -> Population (% world total) | D2: ='DataT4-'!E4 -> National income (PPP 2025 billions €) | E2: ='DataT4-'!F4 -> National income (% world total) | F2: ='DataT4-'!G4 -> Per capita national income (PPP 2025 €) | G2: ='DataT4-'!H4 -> Per capita national income (% world average)
A3: ='DataT4-'!B5 -> East Asia | B3: ='DataT4-'!C5 -> 1652.1856 | C3: ='DataT4-'!D5/100 -> 0.20073858 | D3: ='DataT4-'!E5 -> 30310.742 | E3: ='DataT4-'!F5/100 -> 0.25244657 | F3: ='DataT4-'!G5 -> 18345.845 | G3: ='DataT4-'!H5/100 -> 1.2575887
A4: ='DataT4-'!B6 -> Europe | B4: ='DataT4-'!C6 -> 555.98502 | C4: ='DataT4-'!D6/100 -> 0.067551516 | D4: ='DataT4-'!E6 -> 20201.059 | E4: ='DataT4-'!F6/100 -> 0.16824689 | F4: ='DataT4-'!G6 -> 36333.82 | G4: ='DataT4-'!H6/100 -> 2.4906457
A5: ='DataT4-'!B7 -> Latin America | B5: ='DataT4-'!C7 -> 666.73669 | C5: ='DataT4-'!D7/100 -> 0.081007713 | D5: ='DataT4-'!E7 -> 8669.1455 | E5: ='DataT4-'!F7/100 -> 0.072201995 | F5: ='DataT4-'!G7 -> 13002.353 | G5: ='DataT4-'!H7/100 -> 0.89129779
A6: ='DataT4-'!B8 -> MENA | B6: ='DataT4-'!C8 -> 612.22662 | C6: ='DataT4-'!D8/100 -> 0.074384804 | D6: ='DataT4-'!E8 -> 9423.3006 | E6: ='DataT4-'!F8/100 -> 0.078483064 | F6: ='DataT4-'!G8 -> 15391.851 | G6: ='DataT4-'!H8/100 -> 1.0550954
A7: ='DataT4-'!B9 -> North America & Oceania | B7: ='DataT4-'!C9 -> 433.84502 | C7: ='DataT4-'!D9/100 -> 0.052711652 | D7: ='DataT4-'!E9 -> 20396.536 | E7: ='DataT4-'!F9/100 -> 0.16987494 | F7: ='DataT4-'!G9 -> 47013.414 | G7: ='DataT4-'!H9/100 -> 3.2227208
A8: ='DataT4-'!B10 -> Russia & Central Asia | B8: ='DataT4-'!C10 -> 292.72992 | C8: ='DataT4-'!D10/100 -> 0.035566336 | D8: ='DataT4-'!E10 -> 5964.8477 | E8: ='DataT4-'!F10/100 -> 0.049678934 | F8: ='DataT4-'!G10 -> 20376.625 | G8: ='DataT4-'!H10/100 -> 1.3967965
A9: ='DataT4-'!B11 -> South & South-East Asia | B9: ='DataT4-'!C11 -> 2692.8217 | C9: ='DataT4-'!D11/100 -> 0.32717463 | D9: ='DataT4-'!E11 -> 20456.394 | E9: ='DataT4-'!F11/100 -> 0.17037347 | F9: ='DataT4-'!G11 -> 7596.6386 | G9: ='DataT4-'!H11/100 -> 0.5207417
A10: ='DataT4-'!B12 -> Sub-Saharan Africa | B10: ='DataT4-'!C12 -> 1324.0029 | C10: ='DataT4-'!D12/100 -> 0.16086477 | D10: ='DataT4-'!E12 -> 4645.9292 | E10: ='DataT4-'!F12/100 -> 0.038694166 | F10: ='DataT4-'!G12 -> 3509.0024 | G10: ='DataT4-'!H12/100 -> 0.24053848
A11: ='DataT4-'!B13 -> World | B11: ='DataT4-'!C13 -> 8230.5335 | C11: ='DataT4-'!D13/100 -> 1 | D11: ='DataT4-'!E13 -> 120067.95 | E11: ='DataT4-'!F13/100 -> 1 | F11: ='DataT4-'!G13 -> 14588.113 | G11: ='DataT4-'!H13/100 -> 1
A12: Interpretation. In 2025, per capita national income amounts to a little more than 14 588€ (PPP) worldwide, i.e., 1 216€ per month. Per capita national income, i.e., the income which all individuals would receive with a perfectly egalitarian distribution, varies from an average of little more than 3509€ in Subsaharan Africa (about 292€ per month) to over 47 013€ in North America/Oceania (about 3 917€ per month), i.e., an income scale of 1 to 13. Sources and series: wid.world

Sheet T4a
A1: =DataT4a!B2 -> Table 4a. Per capita national Income by World Region USD-EUR (2025)
B2: =DataT4a!C3 -> PPP 2025 € | D2: =DataT4a!E3 -> 2025 MER € | F2: =DataT4a!G3 -> PPP 2025 $ | H2: =DataT4a!I3 -> 2025 MER $
B3: =DataT4a!C4 -> Per capita national income | C3: =DataT4a!D4 -> Per capita national income (% world total) | D3: =DataT4a!E4 -> Per capita national income | E3: =DataT4a!F4 -> Per capita national income (% world total) | F3: =DataT4a!G4 -> Per capita national income | G3: =DataT4a!H4 -> Per capita national income (% world total) | H3: =DataT4a!I4 -> Per capita national income | I3: =DataT4a!J4 -> Per capita national income (% world total)
A4: =DataT4a!B5 -> East Asia | B4: =DataT4a!C5 -> 18345.845 | C4: =DataT4a!D5/100 -> 1.2575887 | D4: =DataT4a!E5 -> 11435.53 | E4: =DataT4a!F5/100 -> 1.0942949 | F4: =DataT4a!G5 -> 27058.576 | G4: =DataT4a!H5/100 -> 1.2575887 | H4: =DataT4a!I5 -> 13478.333 | I4: =DataT4a!J5/100 -> 1.0942948 | K4: =B4/12 -> 1528.8205
A5: =DataT4a!B6 -> Europe | B5: =DataT4a!C6 -> 36333.82 | C5: =DataT4a!D6/100 -> 2.4906457 | D5: =DataT4a!E6 -> 35941.442 | E5: =DataT4a!F6/100 -> 3.4393277 | F5: =DataT4a!G6 -> 53589.32 | G5: =DataT4a!H6/100 -> 2.4906456 | H5: =DataT4a!I6 -> 42361.895 | I5: =DataT4a!J6/100 -> 3.4393278 | K5: =B5/12 -> 3027.8183
A6: =DataT4a!B7 -> Latin America | B6: =DataT4a!C7 -> 13002.353 | C6: =DataT4a!D7/100 -> 0.89129779 | D6: =DataT4a!E7 -> 8189.9751 | E6: =DataT4a!F7/100 -> 0.78371949 | F6: =DataT4a!G7 -> 19177.373 | G6: =DataT4a!H7/100 -> 0.89129774 | H6: =DataT4a!I7 -> 9653.0032 | I6: =DataT4a!J7/100 -> 0.78371947 | K6: =B6/12 -> 1083.5294
A7: =DataT4a!B8 -> MENA | B7: =DataT4a!C8 -> 15391.851 | C7: =DataT4a!D8/100 -> 1.0550954 | D7: =DataT4a!E8 -> 8084.7489 | E7: =DataT4a!F8/100 -> 0.77365012 | F7: =DataT4a!G8 -> 22701.682 | G7: =DataT4a!H8/100 -> 1.0550954 | H7: =DataT4a!I8 -> 9528.9802 | I7: =DataT4a!J8/100 -> 0.77365014 | K7: =B7/12 -> 1282.6542
A8: =DataT4a!B9 -> North America & Oceania | B8: =DataT4a!C9 -> 47013.414 | C8: =DataT4a!D9/100 -> 3.2227208 | D8: =DataT4a!E9 -> 57715.027 | E8: =DataT4a!F9/100 -> 5.5228973 | F8: =DataT4a!G9 -> 69340.819 | G8: =DataT4a!H9/100 -> 3.2227206 | H8: =DataT4a!I9 -> 68025.032 | I8: =DataT4a!J9/100 -> 5.522897 | K8: =B8/12 -> 3917.7845
A9: =DataT4a!B10 -> Russia & Central Asia | B9: =DataT4a!C10 -> 20376.625 | C9: =DataT4a!D10/100 -> 1.3967965 | D9: =DataT4a!E10 -> 9172.1777 | E9: =DataT4a!F10/100 -> 0.87770895 | F9: =DataT4a!G10 -> 30053.802 | G9: =DataT4a!H10/100 -> 1.3967964 | H9: =DataT4a!I10 -> 10810.664 | I9: =DataT4a!J10/100 -> 0.87770897 | K9: =B9/12 -> 1698.0521
A10: =DataT4a!B11 -> South & South-East Asia | B10: =DataT4a!C11 -> 7596.6386 | C10: =DataT4a!D11/100 -> 0.5207417 | D10: =DataT4a!E11 -> 2581.0309 | E10: =DataT4a!F11/100 -> 0.24698539 | F10: =DataT4a!G11 -> 11204.401 | G10: =DataT4a!H11/100 -> 0.52074168 | H10: =DataT4a!I11 -> 3042.097 | I10: =DataT4a!J11/100 -> 0.24698538 | K10: =B10/12 -> 633.05322
A11: =DataT4a!B12 -> Sub-Saharan Africa | B11: =DataT4a!C12 -> 3509.0024 | C11: =DataT4a!D12/100 -> 0.24053848 | D11: =DataT4a!E12 -> 1547.4416 | E11: =DataT4a!F12/100 -> 0.14807861 | F11: =DataT4a!G12 -> 5175.4827 | G11: =DataT4a!H12/100 -> 0.24053847 | H11: =DataT4a!I12 -> 1823.8711 | I11: =DataT4a!J12/100 -> 0.14807861 | K11: =B11/12 -> 292.41687
A12: =DataT4a!B13 -> World | B12: =DataT4a!C13 -> 14588.113 | C12: =DataT4a!D13/100 -> 1 | D12: =DataT4a!E13 -> 10450.136 | E12: =DataT4a!F13/100 -> 1 | F12: =DataT4a!G13 -> 21516.237 | G12: =DataT4a!H13/100 -> 1 | H12: =DataT4a!I13 -> 12316.911 | I12: =DataT4a!J13/100 -> 1 | K12: =B12/12 -> 1215.6761
A13: Interpretation. In 2025, per capita national income amounts to 14 588€ (PPP) worldwide, i.e., 1 216€ per month. Per capita national income, i.e., theincome which all individuals would receive with a perfectly egalitarian distribution, varies from an average of little more than 3 509€ in Subsaharan Africa (about 292€ per month) to over 47 013€ in North America/Oceania (about 3917€ per month), i.e., an income scale of 1 to 13. Sources and series: wid.world

Sheet T5a
A1: =DataT5a!B3 -> Table 5a. Per Capita National Income Growth PPP 2025 € by World Regions (1800-2025)
B2: =DataT5a!C4 -> 1800 Per capita national income (PPP 2025 €) | C2: =DataT5a!D4 -> 1980 Per capita national income (PPP 2025 €) | D2: =DataT5a!E4 -> 2000 Per capita national income (PPP 2025 €) | E2: =DataT5a!F4 -> 2020 Per capita national income (PPP 2025 €) | F2: =DataT5a!G4 -> 2025 Per capita national income (PPP 2025 €) | G2: =DataT5a!H4 -> Annual growth rate 1800-2025 | H2: =DataT5a!I4 -> Annual growth rate 1980-2025 | I2: =DataT5a!J4 -> Annual growth rate 1980-2000 | ... K2: =DataT5a!L4 -> Annual growth rate 2020-2025
A3: =DataT5a!B5 -> East Asia | B3: =DataT5a!C5 -> 756.87952 | C3: =DataT5a!D5 -> 3203.624 | D3: =DataT5a!E5 -> 5852.9658 | E3: =DataT5a!F5 -> 14669.656 | F3: =DataT5a!G5 -> 18345.846 | G3: =DataT5a!H5 -> 1.4269538 | H3: =DataT5a!I5 -> 3.9542232 | ... K3: =DataT5a!L5 -> 4.5739617
A4: =DataT5a!B6 -> Europe | B4: =DataT5a!C6 -> 1516.1448 | C4: =DataT5a!D6 -> 18521.828 | D4: =DataT5a!E6 -> 26905.697 | E4: =DataT5a!F6 -> 31373.441 | F4: =DataT5a!G6 -> 36333.82 | G4: =DataT5a!H6 -> 1.4218256 | H4: =DataT5a!I6 -> 1.5085975 | ... K4: =DataT5a!L6 -> 2.9792633
A5: =DataT5a!B7 -> Latin America | B5: =DataT5a!C7 -> 770.73651 | C5: =DataT5a!D7 -> 9067.3467 | D5: =DataT5a!E7 -> 9728.6865 | E5: =DataT5a!F7 -> 11199.896 | F5: =DataT5a!G7 -> 13002.353 | G5: =DataT5a!H7 -> 1.2637134 | H5: =DataT5a!I7 -> 0.80421788 | ... K5: =DataT5a!L7 -> 3.0295007
A6: =DataT5a!B8 -> MENA | B6: =DataT5a!C8 -> 696.99304 | C6: =DataT5a!D8 -> 10019.868 | D6: =DataT5a!E8 -> 9918.3545 | E6: =DataT5a!F8 -> 13260.667 | F6: =DataT5a!G8 -> 15391.851 | G6: =DataT5a!H8 -> 1.3849778 | H6: =DataT5a!I8 -> 0.95849383 | ... K6: =DataT5a!L8 -> 3.0255859
A7: =DataT5a!B9 -> North America & Oceania | B7: =DataT5a!C9 -> 1351.0249 | C7: =DataT5a!D9 -> 23183.15 | D7: =DataT5a!E9 -> 35849.449 | E7: =DataT5a!F9 -> 41591.25 | F7: =DataT5a!G9 -> 47013.414 | G7: =DataT5a!H9 -> 1.590096 | H7: =DataT5a!I9 -> 1.5835344 | ... K7: =DataT5a!L9 -> 2.4811435
A8: =DataT5a!B10 -> Russia & Central Asia | B8: =DataT5a!C10 -> 749.38873 | C8: =DataT5a!D10 -> 11946.08 | D8: =DataT5a!E10 -> 10243.371 | E8: =DataT5a!F10 -> 17544.988 | F8: =DataT5a!G10 -> 20376.625 | G8: =DataT5a!H10 -> 1.4787766 | H8: =DataT5a!I10 -> 1.1937023 | ... K8: =DataT5a!L10 -> 3.0376236
A9: =DataT5a!B11 -> South & South-East Asia | B9: =DataT5a!C11 -> 833.79749 | C9: =DataT5a!D11 -> 1616.8258 | D9: =DataT5a!E11 -> 2820.2151 | E9: =DataT5a!F11 -> 5935.7754 | F9: =DataT5a!G11 -> 7596.6387 | G9: =DataT5a!H11 -> 0.98682427 | H9: =DataT5a!I11 -> 3.4981067 | ... K9: =DataT5a!L11 -> 5.0579214
A10: =DataT5a!B12 -> Sub-Saharan Africa | B10: =DataT5a!C12 -> 505.86182 | C10: =DataT5a!D12 -> 2422.375 | D10: =DataT5a!E12 -> 2135.561 | E10: =DataT5a!F12 -> 3225.896 | F10: =DataT5a!G12 -> 3509.0024 | G10: =DataT5a!H12 -> 0.86452609 | H10: =DataT5a!I12 -> 0.82691872 | ... K10: =DataT5a!L12 -> 1.6966536
A11: =DataT5a!B13 -> World | B11: =DataT5a!C13 -> 730.17249 | C11: =DataT5a!D13 -> 7915.1694 | D11: =DataT5a!E13 -> 10036.208 | E11: =DataT5a!F13 -> 12714.921 | F11: =DataT5a!G13 -> 14588.112 | G11: =DataT5a!H13 -> 1.3398664 | H11: =DataT5a!I13 -> 1.3679968 | ... K11: =DataT5a!L13 -> 2.7867393
A12: Interpretation. Between 1800 and 2025, the real growth rate of per capita national income expressed in PPP 2025 € at the global level has been 1.3% per year. Since 1980 we observed almost doubling of average income, with an acceleration in the growth after 2000: 1.5% per year over 2000-2025 and 2.8% over 2020-2025. Sources and series: wid.world

Sheet T5b
A1: =DataT5b!B3 -> Table 5b. Per Capita National Income Growth PPP 2025 $ by World Regions (1800-2025)
B2: =DataT5b!C4 -> 1800 Per capita national income (PPP 2025 $) | C2: =DataT5b!D4 -> 1980 Per capita national income (PPP 2025 $) | D2: =DataT5b!E4 -> 2000 Per capita national income (PPP 2025 $) | E2: =DataT5b!F4 -> 2020 Per capita national income (PPP 2025 $) | F2: =DataT5b!G4 -> 2025 Per capita national income (PPP 2025 $) | G2: =DataT5b!H4 -> Annual growth rate 1800-2025 | H2: =DataT5b!I4 -> Annual growth rate 1980-2025 | I2: =DataT5b!J4 -> Annual growth rate 1980-2000 | ... K2: =DataT5b!L4 -> Annual growth rate 2020-2025
A3: =DataT5b!B5 -> East Asia | B3: =DataT5b!C5 -> 1116.3335 | C3: =DataT5b!D5 -> 4725.0757 | D3: =DataT5b!E5 -> 8632.6309 | E3: =DataT5b!F5 -> 21636.506 | F3: =DataT5b!G5 -> 27058.576 | G3: =DataT5b!H5 -> 1.4269538 | H3: =DataT5b!I5 -> 3.9542232 | ... K3: =DataT5b!L5 -> 4.5739622
A4: =DataT5b!B6 -> Europe | B4: =DataT5b!C6 -> 2236.1858 | C4: =DataT5b!D6 -> 27318.133 | D4: =DataT5b!E6 -> 39683.637 | E4: =DataT5b!F6 -> 46273.18 | F4: =DataT5b!G6 -> 53589.32 | G4: =DataT5b!H6 -> 1.4218256 | H4: =DataT5b!I6 -> 1.5085975 | ... K4: =DataT5b!L6 -> 2.9792635
A5: =DataT5b!B7 -> Latin America | B5: =DataT5b!C7 -> 1136.7714 | C5: =DataT5b!D7 -> 13373.572 | D5: =DataT5b!E7 -> 14348.992 | E5: =DataT5b!F7 -> 16518.9 | F5: =DataT5b!G7 -> 19177.373 | G5: =DataT5b!H7 -> 1.2637134 | H5: =DataT5b!I7 -> 0.80421788 | ... K5: =DataT5b!L7 -> 3.0295017
A6: =DataT5b!B8 -> MENA | B6: =DataT5b!C8 -> 1028.006 | C6: =DataT5b!D8 -> 14778.461 | D6: =DataT5b!E8 -> 14628.737 | E6: =DataT5b!F8 -> 19558.365 | F6: =DataT5b!G8 -> 22701.682 | G6: =DataT5b!H8 -> 1.3849778 | H6: =DataT5b!I8 -> 0.95849377 | ... K6: =DataT5b!L8 -> 3.0255859
A7: =DataT5b!B9 -> North America & Oceania | B7: =DataT5b!C9 -> 1992.6476 | C7: =DataT5b!D9 -> 34193.191 | D7: =DataT5b!E9 -> 52874.918 | E7: =DataT5b!F9 -> 61343.59 | F7: =DataT5b!G9 -> 69340.82 | G7: =DataT5b!H9 -> 1.590096 | H7: =DataT5b!I9 -> 1.5835344 | ... K7: =DataT5b!L9 -> 2.4811425
A8: =DataT5b!B10 -> Russia & Central Asia | B8: =DataT5b!C10 -> 1105.2852 | C8: =DataT5b!D10 -> 17619.461 | D8: =DataT5b!E10 -> 15108.108 | E8: =DataT5b!F10 -> 25877.379 | F8: =DataT5b!G10 -> 30053.803 | G8: =DataT5b!H10 -> 1.4787766 | H8: =DataT5b!I10 -> 1.1937022 | ... K8: =DataT5b!L10 -> 3.0376227
A9: =DataT5b!B11 -> South & South-East Asia | B9: =DataT5b!C11 -> 1229.781 | C9: =DataT5b!D11 -> 2384.6816 | D9: =DataT5b!E11 -> 4159.5796 | E9: =DataT5b!F11 -> 8754.7686 | F9: =DataT5b!G11 -> 11204.401 | G9: =DataT5b!H11 -> 0.98682421 | H9: =DataT5b!I11 -> 3.4981067 | ... K9: =DataT5b!L11 -> 5.0579205
A10: =DataT5b!B12 -> Sub-Saharan Africa | B10: =DataT5b!C12 -> 746.10358 | C10: =DataT5b!D12 -> 3572.7988 | D10: =DataT5b!E12 -> 3149.7725 | E10: =DataT5b!F12 -> 4757.9248 | F10: =DataT5b!G12 -> 5175.4829 | G10: =DataT5b!H12 -> 0.86452609 | H10: =DataT5b!I12 -> 0.82691878 | ... K10: =DataT5b!L12 -> 1.6966534
A11: =DataT5b!B13 -> World | B11: =DataT5b!C13 -> 1076.9429 | C11: =DataT5b!D13 -> 11674.208 | D11: =DataT5b!E13 -> 14802.561 | E11: =DataT5b!F13 -> 18753.436 | F11: =DataT5b!G13 -> 21516.236 | G11: =DataT5b!H13 -> 1.3398664 | H11: =DataT5b!I13 -> 1.3679968 | ... K11: =DataT5b!L13 -> 2.7867401
A12: Interpretation. Between 1800 and 2025, the real growth rate of per capita national income expressed in PPP 2025 $ at the global level has been 1.3% per year. Since 1980 we observed almost doubling of average income, with an acceleration in the growth after 2000: 1.5% per year over 2000-2025 and 2.8% over 2020-2025. Sources and series: wid.world

Sheet T5c
A1: =DataT5c!B3 -> Table 5c. Per Capita National Income Growth MER 2025 € by World Regions (1800-2025)
B2: =DataT5c!C4 -> 1800 Per capita national income (MER €) | C2: =DataT5c!D4 -> 1980 Per capita national income (MER €) | D2: =DataT5c!E4 -> 2000 Per capita national income (MER €) | E2: =DataT5c!F4 -> 2020 Per capita national income (MER €) | F2: =DataT5c!G4 -> 2025 Per capita national income (MER €) | G2: =DataT5c!H4 -> Annual growth rate 1800-2025 | H2: =DataT5c!I4 -> Annual growth rate 1980-2025 | I2: =DataT5c!J4 -> Annual growth rate 1980-2000 | ... K2: =DataT5c!L4 -> Annual growth rate 2020-2025
A3: =DataT5c!B5 -> East Asia | B3: =DataT5c!C5 -> 461.95917 | C3: =DataT5c!D5 -> 2053.4666 | D3: =DataT5c!E5 -> 3870.8618 | E3: =DataT5c!F5 -> 9194.4082 | F3: =DataT5c!G5 -> 11435.53 | G3: =DataT5c!H5 -> 1.4364431 | H3: =DataT5c!I5 -> 3.8897347 | ... K3: =DataT5c!L5 -> 4.4591532
A4: =DataT5c!B6 -> Europe | B4: =DataT5c!C6 -> 1511.7633 | C4: =DataT5c!D6 -> 18245.855 | D4: =DataT5c!E6 -> 26990.402 | E4: =DataT5c!F6 -> 31119.236 | F4: =DataT5c!G6 -> 35941.441 | G4: =DataT5c!H6 -> 1.4182359 | H4: =DataT5c!I6 -> 1.5179682 | ... K4: =DataT5c!L6 -> 2.9232075
A5: =DataT5c!B7 -> Latin America | B5: =DataT5c!C7 -> 509.2695 | C5: =DataT5c!D7 -> 5863.7632 | D5: =DataT5c!E7 -> 6267.3989 | E5: =DataT5c!F7 -> 7080.0942 | F5: =DataT5c!G7 -> 8189.9751 | G5: =DataT5c!H7 -> 1.2421801 | H5: =DataT5c!I7 -> 0.74525058 | ... K5: =DataT5c!L7 -> 2.9553001
A6: =DataT5c!B8 -> MENA | B6: =DataT5c!C8 -> 364.85007 | C6: =DataT5c!D8 -> 5337.6904 | D6: =DataT5c!E8 -> 5180.8804 | E6: =DataT5c!F8 -> 6948.0586 | F6: =DataT5c!G8 -> 8084.749 | G6: =DataT5c!H8 -> 1.3865235 | H6: =DataT5c!I8 -> 0.92690587 | ... K6: =DataT5c!L8 -> 3.076725
A7: =DataT5c!B9 -> North America & Oceania | B7: =DataT5c!C9 -> 1650.8887 | C7: =DataT5c!D9 -> 28446.799 | D7: =DataT5c!E9 -> 44061.113 | E7: =DataT5c!F9 -> 51057.941 | F7: =DataT5c!G9 -> 57715.027 | G7: =DataT5c!H9 -> 1.5921885 | H7: =DataT5c!I9 -> 1.5846059 | ... K7: =DataT5c!L9 -> 2.481416
A8: =DataT5c!B10 -> Russia & Central Asia | B8: =DataT5c!C10 -> 335.36237 | C8: =DataT5c!D10 -> 5265.4941 | D8: =DataT5c!E10 -> 4644.585 | E8: =DataT5c!F10 -> 7884.3892 | F8: =DataT5c!G10 -> 9172.1777 | G8: =DataT5c!H10 -> 1.4814072 | H8: =DataT5c!I10 -> 1.2409698 | ... K8: =DataT5c!L10 -> 3.0720422
A9: =DataT5c!B11 -> South & South-East Asia | B9: =DataT5c!C11 -> 268.45117 | C9: =DataT5c!D11 -> 561.28772 | D9: =DataT5c!E11 -> 990.20026 | E9: =DataT5c!F11 -> 2038.0701 | F9: =DataT5c!G11 -> 2581.0308 | G9: =DataT5c!H11 -> 1.0109762 | H9: =DataT5c!I11 -> 3.4485993 | ... K9: =DataT5c!L11 -> 4.8370557
A10: =DataT5c!B12 -> Sub-Saharan Africa | B10: =DataT5c!C12 -> 241.07956 | C10: =DataT5c!D12 -> 1107.356 | D10: =DataT5c!E12 -> 1175.5726 | E10: =DataT5c!F12 -> 1484.6976 | F10: =DataT5c!G12 -> 1547.4417 | G10: =DataT5c!H12 -> 0.82974851 | H10: =DataT5c!I12 -> 0.74638915 | ... K10: =DataT5c!L12 -> 0.83127367
A11: =DataT5c!B13 -> World | B11: =DataT5c!C13 -> 523.05615 | C11: =DataT5c!D13 -> 5670.0005 | D11: =DataT5c!E13 -> 7189.3979 | E11: =DataT5c!F13 -> 9108.2822 | F11: =DataT5c!G13 -> 10450.136 | G11: =DataT5c!H13 -> 1.3398664 | H11: =DataT5c!I13 -> 1.3679967 | ... K11: =DataT5c!L13 -> 2.7867393
A12: Interpretation. Between 1800 and 2025, the real growth rate of per capita national income expressed in MER € at the global level has been 1.3% per year. Since 1980 we observed almost doubling of average income, with an acceleration in the growth after 2000: 1.5% per year over 2000-2025 and 2.8% over 2020-2025. Sources and series: wid.world

Sheet T5d
A1: =DataT5d!B3 -> Table 5d. Per Capita National Income Growth MER 2025 $ by World Regions (1800-2025)
B2: =DataT5d!C4 -> 1800 Per capita national income (MER $) | C2: =DataT5d!D4 -> 1980 Per capita national income (MER $) | D2: =DataT5d!E4 -> 2000 Per capita national income (MER $) | E2: =DataT5d!F4 -> 2020 Per capita national income (MER $) | F2: =DataT5d!G4 -> 2025 Per capita national income (MER $) | G2: =DataT5d!H4 -> Annual growth rate 1800-2025 | H2: =DataT5d!I4 -> Annual growth rate 1980-2025 | I2: =DataT5d!J4 -> Annual growth rate 1980-2000 | ... K2: =DataT5d!L4 -> Annual growth rate 2020-2025
A3: =DataT5d!B5 -> East Asia | B3: =DataT5d!C5 -> 544.48193 | C3: =DataT5d!D5 -> 2420.2905 | D3: =DataT5d!E5 -> 4562.3389 | E3: =DataT5d!F5 -> 10836.865 | F3: =DataT5d!G5 -> 13478.333 | G3: =DataT5d!H5 -> 1.4364431 | H3: =DataT5d!I5 -> 3.8897347 | ... K3: =DataT5d!L5 -> 4.4591532
A4: =DataT5d!B6 -> Europe | B4: =DataT5d!C6 -> 1781.8195 | C4: =DataT5d!D6 -> 21505.23 | D4: =DataT5d!E6 -> 31811.871 | E4: =DataT5d!F6 -> 36678.27 | F4: =DataT5d!G6 -> 42361.895 | G4: =DataT5d!H6 -> 1.4182359 | H4: =DataT5d!I6 -> 1.5179682 | ... K4: =DataT5d!L6 -> 2.9232073
A5: =DataT5d!B7 -> Latin America | B5: =DataT5d!C7 -> 600.24359 | C5: =DataT5d!D7 -> 6911.2451 | D5: =DataT5d!E7 -> 7386.9854 | E5: =DataT5d!F7 -> 8344.8574 | F5: =DataT5d!G7 -> 9653.0029 | G5: =DataT5d!H7 -> 1.2421801 | H5: =DataT5d!I7 -> 0.74525058 | ... K5: =DataT5d!L7 -> 2.9552999
A6: =DataT5d!B8 -> MENA | B6: =DataT5d!C8 -> 430.0256 | C6: =DataT5d!D8 -> 6291.1963 | D6: =DataT5d!E8 -> 6106.3745 | E6: =DataT5d!F8 -> 8189.2354 | F6: =DataT5d!G8 -> 9528.9805 | G6: =DataT5d!H8 -> 1.3865235 | H6: =DataT5d!I8 -> 0.92690593 | ... K6: =DataT5d!L8 -> 3.0767255
A7: =DataT5d!B9 -> North America & Oceania | B7: =DataT5d!C9 -> 1945.7975 | C7: =DataT5d!D9 -> 33528.434 | D7: =DataT5d!E9 -> 51932.031 | E7: =DataT5d!F9 -> 60178.754 | F7: =DataT5d!G9 -> 68025.031 | G7: =DataT5d!H9 -> 1.5921885 | H7: =DataT5d!I9 -> 1.5846058 | ... K7: =DataT5d!L9 -> 2.4814148
A8: =DataT5d!B10 -> Russia & Central Asia | B8: =DataT5d!C10 -> 395.27032 | C8: =DataT5d!D10 -> 6206.1035 | D8: =DataT5d!E10 -> 5474.2769 | E8: =DataT5d!F10 -> 9292.8281 | F8: =DataT5d!G10 -> 10810.663 | G8: =DataT5d!H10 -> 1.4814072 | H8: =DataT5d!I10 -> 1.2409698 | ... K8: =DataT5d!L10 -> 3.0720434
A9: =DataT5d!B11 -> South & South-East Asia | B9: =DataT5d!C11 -> 316.40631 | C9: =DataT5d!D11 -> 661.5542 | D9: =DataT5d!E11 -> 1167.0862 | E9: =DataT5d!F11 -> 2402.1438 | F9: =DataT5d!G11 -> 3042.0969 | G9: =DataT5d!H11 -> 1.0109762 | H9: =DataT5d!I11 -> 3.4485993 | ... K9: =DataT5d!L11 -> 4.8370552
A10: =DataT5d!B12 -> Sub-Saharan Africa | B10: =DataT5d!C12 -> 284.14514 | C10: =DataT5d!D12 -> 1305.1702 | D10: =DataT5d!E12 -> 1385.5729 | E10: =DataT5d!F12 -> 1749.9187 | F10: =DataT5d!G12 -> 1823.8711 | G10: =DataT5d!H12 -> 0.82974851 | H10: =DataT5d!I12 -> 0.74638915 | ... K10: =DataT5d!L12 -> 0.83127379
A11: =DataT5d!B13 -> World | B11: =DataT5d!C13 -> 616.49304 | C11: =DataT5d!D13 -> 6682.8691 | D11: =DataT5d!E13 -> 8473.6865 | E11: =DataT5d!F13 -> 10735.354 | F11: =DataT5d!G13 -> 12316.911 | G11: =DataT5d!H13 -> 1.3398664 | H11: =DataT5d!I13 -> 1.3679967 | ... K11: =DataT5d!L13 -> 2.7867384
A12: Interpretation. Between 1800 and 2025, the real growth rate of per capita national income expressed in MER $ at the global level has been 1.3% per year. Since 1980 we observed almost doubling of average income, with an acceleration in the growth after 2000: 1.5% per year over 2000-2025 and 2.8% over 2020-2025. Sources and series: wid.world

Sheet T6
A1: =DataT6!B3 -> Table 6. Per Capita National Income Growth PPP 2025 € by WID core Territories (1980-2025)
A2: =DataT6!B4 -> Region | B2: =DataT6!C4 -> Country | C2: =DataT6!D4 -> 1800 Per capita national income (PPP 2025 €) | D2: =DataT6!E4 -> 1980 Per capita national income (PPP 2025 €) | E2: =DataT6!F4 -> 2000 Per capita national income (PPP 2025 €) | F2: =DataT6!G4 -> 2020 Per capita national income (PPP 2025 €) | G2: =DataT6!H4 -> 2025 Per capita national income (PPP 2025 €) | H2: =DataT6!I4 -> Annual growth rate 1800-2025 | ... L2: =DataT6!M4 -> Annual growth rate 2020-2025
A3: =DataT6!B5 -> East Asia | B3: =DataT6!C5 -> Taiwan | C3: =DataT6!D5 -> 762.37421 | D3: =DataT6!E5 -> 6466.3774 | E3: =DataT6!F5 -> 22022.65 | F3: =DataT6!G5 -> 41774.199 | G3: =DataT6!H5 -> 55286.777 | H3: =DataT6!I5 -> 1.9221745 | ... L3: =DataT6!M5 -> 5.7651582
B4: =DataT6!C6 -> South Korea | C4: =DataT6!D6 -> 564.92633 | D4: =DataT6!E6 -> 4334.2769 | E4: =DataT6!F6 -> 17094.975 | F4: =DataT6!G6 -> 31462.213 | G4: =DataT6!H6 -> 35047.836 | H4: =DataT6!I6 -> 1.8514977 | I4: =DataT6!J6 -> 4.7543583 | ... L4: =DataT6!M6 -> 2.1819987
B5: =DataT6!C7 -> Japan | C5: =DataT6!D7 -> 807.88416 | D5: =DataT6!E7 -> 15316.253 | E5: =DataT6!F7 -> 23818.285 | F5: =DataT6!G7 -> 26677.477 | G5: =DataT6!H7 -> 30128.635 | H5: =DataT6!I7 -> 1.621365 | I5: =DataT6!J7 -> 1.5148289 | ... L5: =DataT6!M7 -> 2.4629695
B6: =DataT6!C8 -> Other East Asia | C6: =DataT6!D8 -> 1452.4775 | D6: =DataT6!E8 -> 7102.3613 | E6: =DataT6!F8 -> 12931.475 | F6: =DataT6!G8 -> 21507.312 | G6: =DataT6!H8 -> 26422.281 | H6: =DataT6!I8 -> 1.2976527 | I6: =DataT6!J8 -> 2.9625473 | ... L6: =DataT6!M8 -> 4.2021871
B7: =DataT6!C9 -> China | C7: =DataT6!D9 -> 745.72699 | D7: =DataT6!E9 -> 1160.798 | E7: =DataT6!F9 -> 3007.4492 | F7: =DataT6!G9 -> 12333.229 | G7: =DataT6!H9 -> 15891.335 | H7: =DataT6!I9 -> 1.368916 | I7: =DataT6!J9 -> 5.9871993 | ... L7: =DataT6!M9 -> 5.2002368
A8: =DataT6!B10 -> Europe | B8: =DataT6!C10 -> Norway | C8: =DataT6!D10 -> 1622.7782 | D8: =DataT6!E10 -> 29528.547 | E8: =DataT6!F10 -> 51834.059 | F8: =DataT6!G10 -> 63179.25 | G8: =DataT6!H10 -> 70146.875 | H8: =DataT6!I10 -> 1.688068 | ... L8: =DataT6!M10 -> 2.1143498
B9: =DataT6!C11 -> Denmark | C9: =DataT6!D11 -> 1648.1161 | D9: =DataT6!E11 -> 23564.93 | E9: =DataT6!F11 -> 37408.625 | F9: =DataT6!G11 -> 44730.328 | G9: =DataT6!H11 -> 49726.016 | H9: =DataT6!I11 -> 1.5256975 | I9: =DataT6!J11 -> 1.6733319 | ... L9: =DataT6!M11 -> 2.14011
B10: =DataT6!C12 -> Netherlands | C10: =DataT6!D12 -> 2572.5249 | D10: =DataT6!E12 -> 25348.957 | E10: =DataT6!F12 -> 36834.434 | F10: =DataT6!G12 -> 42004.16 | G10: =DataT6!H12 -> 47551.422 | H10: =DataT6!I12 -> 1.3048505 | I10: =DataT6!J12 -> 1.4077593 | ... L10: =DataT6!M12 -> 2.5118902
B11: =DataT6!C13 -> Sweden | C11: =DataT6!D13 -> 1089.9889 | D11: =DataT6!E13 -> 23006.529 | E11: =DataT6!F13 -> 31703.746 | F11: =DataT6!G13 -> 41712.273 | G11: =DataT6!H13 -> 45180.148 | H11: =DataT6!I13 -> 1.6691055 | I11: =DataT6!J13 -> 1.5110351 | ... L11: =DataT6!M13 -> 1.6100713
B12: =DataT6!C14 -> Germany | C12: =DataT6!D14 -> 1810.4558 | D12: =DataT6!E14 -> 23004.826 | E12: =DataT6!F14 -> 33185.5 | F12: =DataT6!G14 -> 39611.574 | G12: =DataT6!H14 -> 41797.828 | H12: =DataT6!I14 -> 1.405008 | I12: =DataT6!J14 -> 1.335822 | ... L12: =DataT6!M14 -> 1.0802532
B13: =DataT6!C15 -> Other Western Europe | C13: =DataT6!D15 -> 1593.2117 | D13: =DataT6!E15 -> 21152.529 | E13: =DataT6!F15 -> 31288.102 | F13: =DataT6!G15 -> 34622.328 | G13: =DataT6!H15 -> 41160.832 | H13: =DataT6!I15 -> 1.4557093 | I13: =DataT6!J15 -> 1.4903919 | ... L13: =DataT6!M15 -> 3.5203128
B14: =DataT6!C16 -> United Kingdom | C14: =DataT6!D16 -> 2975.6355 | D14: =DataT6!E16 -> 17819.709 | E14: =DataT6!F16 -> 31424.762 | F14: =DataT6!G16 -> 32126.607 | G14: =DataT6!H16 -> 38013.445 | H14: =DataT6!I16 -> 1.1386482 | I14: =DataT6!J16 -> 1.697886 | ... L14: =DataT6!M16 -> 3.4223678
B15: =DataT6!C17 -> France | C15: =DataT6!D17 -> 1256.853 | D15: =DataT6!E17 -> 22009.463 | E15: =DataT6!F17 -> 31651.006 | F15: =DataT6!G17 -> 32877.523 | G15: =DataT6!H17 -> 37176.402 | H15: =DataT6!I17 -> 1.516749 | I15: =DataT6!J17 -> 1.1717039 | ... L15: =DataT6!M17 -> 2.4881487
B16: =DataT6!C18 -> Italy | C16: =DataT6!D18 -> 2109.2439 | D16: =DataT6!E18 -> 23224.664 | E16: =DataT6!F18 -> 33868.824 | F16: =DataT6!G18 -> 29077.705 | G16: =DataT6!H18 -> 34700.133 | H16: =DataT6!I18 -> 1.2524061 | I16: =DataT6!J18 -> 0.89627874 | ... L16: =DataT6!M18 -> 3.5986753
B17: =DataT6!C19 -> Spain | C17: =DataT6!D19 -> 1585.5116 | D17: =DataT6!E19 -> 17104.926 | E17: =DataT6!F19 -> 26827.758 | F17: =DataT6!G19 -> 26928.865 | G17: =DataT6!H19 -> 33533.711 | H17: =DataT6!I19 -> 1.3655256 | I17: =DataT6!J19 -> 1.5072119 | ... L17: =DataT6!M19 -> 4.4847035
B18: =DataT6!C20 -> Eastern Europe | C18: =DataT6!D20 -> 646.91724 | D18: =DataT6!E20 -> 10442.181 | E18: =DataT6!F20 -> 11076.905 | F18: =DataT6!G20 -> 21551.023 | G18: =DataT6!H20 -> 25895.305 | H18: =DataT6!I20 -> 1.6533405 | I18: =DataT6!J20 -> 2.0387444 | ... L18: =DataT6!M20 -> 3.7410452
A19: =DataT6!B21 -> Latin America | B19: =DataT6!C21 -> Argentina | C19: =DataT6!D21 -> 976.75232 | D19: =DataT6!E21 -> 15854.797 | E19: =DataT6!F21 -> 15526.597 | F19: =DataT6!G21 -> 17498.039 | G19: =DataT6!H21 -> 20248.16 | H19: =DataT6!I21 -> 1.3564895 | ... L19: =DataT6!M21 -> 2.962538
B20: =DataT6!C22 -> Chile | C20: =DataT6!D22 -> 600.43573 | D20: =DataT6!E22 -> 6160.0034 | E20: =DataT6!F22 -> 11588.76 | F20: =DataT6!G22 -> 16560.623 | G20: =DataT6!H22 -> 19354.293 | H20: =DataT6!I22 -> 1.5555362 | I20: =DataT6!J22 -> 2.57672 | ... L20: =DataT6!M22 -> 3.1668396
B21: =DataT6!C23 -> Mexico | C21: =DataT6!D23 -> 1052.4484 | D21: =DataT6!E23 -> 12415.942 | E21: =DataT6!F23 -> 13548.574 | F21: =DataT6!G23 -> 11943.775 | G21: =DataT6!H23 -> 13822.125 | H21: =DataT6!I23 -> 1.1510863 | I21: =DataT6!J23 -> 0.23870505 | ... L21: =DataT6!M23 -> 2.9642928
B22: =DataT6!C24 -> Brazil | C22: =DataT6!D24 -> 722.03461 | D22: =DataT6!E24 -> 8915.9453 | E22: =DataT6!F24 -> 9569.7793 | F22: =DataT6!G24 -> 11504.803 | G22: =DataT6!H24 -> 13109.847 | H22: =DataT6!I24 -> 1.2968013 | I22: =DataT6!J24 -> 0.8603965 | ... L22: =DataT6!M24 -> 2.6463923
B23: =DataT6!C25 -> Colombia | C23: =DataT6!D25 -> 832.60352 | D23: =DataT6!E25 -> 6324.7832 | E23: =DataT6!F25 -> 7518.2021 | F23: =DataT6!G25 -> 10805.216 | G23: =DataT6!H25 -> 12763.927 | H23: =DataT6!I25 -> 1.2206434 | I23: =DataT6!J25 -> 1.5725639 | ... L23: =DataT6!M25 -> 3.3880086
B24: =DataT6!C26 -> Other Latin America | C24: =DataT6!D26 -> 544.88599 | D24: =DataT6!E26 -> 6880.4141 | E24: =DataT6!F26 -> 6952.5767 | F24: =DataT6!G26 -> 8655.6992 | G24: =DataT6!H26 -> 10159.311 | H24: =DataT6!I26 -> 1.3087431 | I24: =DataT6!J26 -> 0.86978698 | ... L24: =DataT6!M26 -> 3.2553163
A25: =DataT6!B27 -> MENA | B25: =DataT6!C27 -> United Arab Emirates | C25: =DataT6!D27 -> 448.92169 | D25: =DataT6!E27 -> 122996.63 | E25: =DataT6!F27 -> 65164.047 | F25: =DataT6!G27 -> 48366.523 | G25: =DataT6!H27 -> 53645.613 | H25: =DataT6!I27 -> 2.1486726 | ... L25: =DataT6!M27 -> 2.0934465
B26: =DataT6!C28 -> Saudi Arabia | C26: =DataT6!D28 -> 1031.3004 | D26: =DataT6!E28 -> 103553.73 | E26: =DataT6!F28 -> 40415.008 | F26: =DataT6!G28 -> 41351.004 | G26: =DataT6!H28 -> 48625.164 | H26: =DataT6!I28 -> 1.7273358 | I26: =DataT6!J28 -> -1.665856 | ... L26: =DataT6!M28 -> 3.2939782
B27: =DataT6!C29 -> Turkiye | C27: =DataT6!D29 -> 602.97614 | D27: =DataT6!E29 -> 6594.0449 | E27: =DataT6!F29 -> 9733.1055 | F27: =DataT6!G29 -> 18187.838 | G27: =DataT6!H29 -> 24358.051 | H27: =DataT6!I29 -> 1.6574706 | I27: =DataT6!J29 -> 2.9463382 | ... L27: =DataT6!M29 -> 6.0162134
B28: =DataT6!C30 -> Egypt | C28: =DataT6!D30 -> 804.67749 | D28: =DataT6!E30 -> 4924.4355 | E28: =DataT6!F30 -> 8226.293 | F28: =DataT6!G30 -> 11830.522 | G28: =DataT6!H30 -> 13136.62 | H28: =DataT6!I30 -> 1.2489427 | I28: =DataT6!J30 -> 2.2043767 | ... L28: =DataT6!M30 -> 2.1165056
B29: =DataT6!C31 -> Algeria | C29: =DataT6!D31 -> 642.2785 | D29: =DataT6!E31 -> 7829.6885 | E29: =DataT6!F31 -> 8054.2549 | F29: =DataT6!G31 -> 9950.3496 | G29: =DataT6!H31 -> 11393.849 | H29: =DataT6!I31 -> 1.2863394 | I29: =DataT6!J31 -> 0.83715332 | ... L29: =DataT6!M31 -> 2.7463539
B30: =DataT6!C32 -> Other MENA | C30: =DataT6!D32 -> 1014.0021 | D30: =DataT6!E32 -> 8818.6758 | E30: =DataT6!F32 -> 8632.3516 | F30: =DataT6!G32 -> 9742.6602 | G30: =DataT6!H32 -> 9848.6885 | H30: =DataT6!I32 -> 1.0155367 | I30: =DataT6!J32 -> 0.24578275 | ... L30: =DataT6!M32 -> 0.21671641
B31: =DataT6!C33 -> Iran | C31: =DataT6!D33 -> 502.86456 | D31: =DataT6!E33 -> 6538.2236 | E31: =DataT6!F33 -> 6334.3315 | F31: =DataT6!G33 -> 7443.2759 | G31: =DataT6!H33 -> 9042.7969 | H31: =DataT6!I33 -> 1.2924601 | I31: =DataT6!J33 -> 0.7232765 | ... L31: =DataT6!M33 -> 3.9699264
B32: =DataT6!C34 -> Morocco | C32: =DataT6!D34 -> 505.73511 | D32: =DataT6!E34 -> 2609.3403 | E32: =DataT6!F34 -> 3288.4707 | F32: =DataT6!G34 -> 6066.0781 | G32: =DataT6!H34 -> 7146.0513 | H32: =DataT6!I34 -> 1.1839774 | I32: =DataT6!J34 -> 2.264055 | ... L32: =DataT6!M34 -> 3.3312366
A33: =DataT6!B35 -> North America & Oceania | B33: =DataT6!C35 -> USA | C33: =DataT6!D35 -> 1777.0096 | D33: =DataT6!E35 -> 23764.225 | E33: =DataT6!F35 -> 37661.988 | F33: =DataT6!G35 -> 43821.824 | G33: =DataT6!H35 -> 49940.434 | H33: =DataT6!I35 -> 1.4936671 | ... L33: =DataT6!M35 -> 2.6484447
B34: =DataT6!C36 -> Canada | C34: =DataT6!D36 -> 1000.8845 | D34: =DataT6!E36 -> 23569.922 | E34: =DataT6!F36 -> 32637.424 | F34: =DataT6!G36 -> 37533.629 | G34: =DataT6!H36 -> 42166.84 | H34: =DataT6!I36 -> 1.6764529 | I34: =DataT6!J36 -> 1.3009738 | ... L34: =DataT6!M36 -> 2.3552454
B35: =DataT6!C37 -> Australia | C35: =DataT6!D37 -> 847.40851 | D35: =DataT6!E37 -> 21172.516 | E35: =DataT6!F37 -> 30623.172 | F35: =DataT6!G37 -> 38907.602 | G35: =DataT6!H37 -> 41639.902 | H35: =DataT6!I37 -> 1.746015 | I35: =DataT6!J37 -> 1.5143632 | ... L35: =DataT6!M37 -> 1.3666396
B36: =DataT6!C38 -> New Zealand | C36: =DataT6!D38 -> 761.20264 | D36: =DataT6!E38 -> 16853.344 | E36: =DataT6!F38 -> 20553.406 | F36: =DataT6!G38 -> 31809.367 | G36: =DataT6!H38 -> 32442.963 | H36: =DataT6!I38 -> 1.6816902 | I36: =DataT6!J38 -> 1.4660525 | ... L36: =DataT6!M38 -> 0.39523336
B37: =DataT6!C39 -> Other North America & Oceania | C37: =DataT6!D39 -> 311.58298 | D37: =DataT6!E39 -> 4737.187 | E37: =DataT6!F39 -> 5402.9712 | F37: =DataT6!G39 -> 4803.7461 | G37: =DataT6!H39 -> 4771.292 | H37: =DataT6!I39 -> 1.2201422 | I37: =DataT6!J39 -> 0.015942549 | ... L37: =DataT6!M39 -> -0.13548619
A38: =DataT6!B40 -> Russia & Central Asia | B38: =DataT6!C40 -> Russia | C38: =DataT6!D40 -> 807.11578 | D38: =DataT6!E40 -> 13502.185 | E38: =DataT6!F40 -> 14894.996 | F38: =DataT6!G40 -> 24669.295 | G38: =DataT6!H40 -> 29058.408 | H38: =DataT6!I40 -> 1.6054605 | ... L38: =DataT6!M40 -> 3.3291869
B39: =DataT6!C41 -> Other Russia & Central Asia | C39: =DataT6!D41 -> 655.97595 | D39: =DataT6!E41 -> 9870.208 | E39: =DataT6!F41 -> 4965.7236 | F39: =DataT6!G41 -> 10406.147 | G39: =DataT6!H41 -> 11971.24 | H39: =DataT6!I41 -> 1.299094 | I39: =DataT6!J41 -> 0.42977932 | ... L39: =DataT6!M41 -> 2.8418405
A40: =DataT6!B42 -> South & South-East Asia | B40: =DataT6!C42 -> Thailand | C40: =DataT6!D42 -> 791.96613 | D40: =DataT6!E42 -> 3928.2195 | E40: =DataT6!F42 -> 8030.6611 | F40: =DataT6!G42 -> 12422.272 | G40: =DataT6!H42 -> 14093.052 | H40: =DataT6!I42 -> 1.2877402 | ... L40: =DataT6!M42 -> 2.5559344
...

Sheet T7
A1: =DataT7!B3 -> Table 7. Population by World Regions (1800-2025)
B2: =DataT7!C4 -> 1800 Population (millions) | C2: =DataT7!D4 -> 1980 Population (millions) | D2: =DataT7!E4 -> 2000 Population (millions) | E2: =DataT7!F4 -> 2020 Population (millions) | F2: =DataT7!G4 -> 2025 Population (millions) | G2: =DataT7!H4 -> Ratio 2025/1800 | H2: =DataT7!I4 -> Annual growth rate 1800-2025 | I2: =DataT7!J4 -> Annual growth rate 1980-2025 | ... L2: =DataT7!M4 -> Annual growth rate 2020-2025
A3: =DataT7!B5 -> East Asia | B3: =DataT7!C5 -> 400.53827 | C3: =DataT7!D5 -> 1182.8966 | D3: =DataT7!E5 -> 1498.9716 | E3: =DataT7!F5 -> 1665.533 | F3: =DataT7!G5 -> 1652.1857 | G3: =DataT7!H5 -> 4.1249132 | H3: =DataT7!I5 -> 0.63178515 | ... L3: =DataT7!M5 -> -0.16079363
A4: =DataT7!B6 -> Europe | B4: =DataT7!C6 -> 145.62494 | C4: =DataT7!D6 -> 498.12009 | D4: =DataT7!E6 -> 524.72095 | E4: =DataT7!F6 -> 552.56982 | F4: =DataT7!G6 -> 555.98505 | G4: =DataT7!H6 -> 3.8179245 | H4: =DataT7!I6 -> 0.59720147 | ... L4: =DataT7!M6 -> 0.12330764
A5: =DataT7!B7 -> Latin America | B5: =DataT7!C7 -> 17.609682 | C5: =DataT7!D7 -> 359.65326 | D5: =DataT7!E7 -> 520.17303 | E5: =DataT7!F7 -> 645.54279 | F5: =DataT7!G7 -> 666.73669 | G5: =DataT7!H7 -> 37.861938 | H5: =DataT7!I7 -> 1.6282003 | ... L5: =DataT7!M7 -> 0.64816612
A6: =DataT7!B8 -> MENA | B6: =DataT7!C8 -> 37.663643 | C6: =DataT7!D8 -> 229.96655 | D6: =DataT7!E8 -> 384.21326 | E6: =DataT7!F8 -> 566.16345 | F6: =DataT7!G8 -> 612.22662 | G6: =DataT7!H8 -> 16.255108 | H6: =DataT7!I8 -> 1.2470032 | ... L6: =DataT7!M8 -> 1.5766952
A7: =DataT7!B9 -> North America & Oceania | B7: =DataT7!C9 -> 9.2114439 | C7: =DataT7!D9 -> 277.25616 | D7: =DataT7!E9 -> 343.52652 | E7: =DataT7!F9 -> 421.51688 | F7: =DataT7!G9 -> 433.84503 | G7: =DataT7!H9 -> 47.09848 | H7: =DataT7!I9 -> 1.7268475 | ... L7: =DataT7!M9 -> 0.57821703
A8: =DataT7!B10 -> Russia & Central Asia | B8: =DataT7!C10 -> 42.272114 | C8: =DataT7!D10 -> 254.01833 | D8: =DataT7!E10 -> 278.07523 | E8: =DataT7!F10 -> 293.70242 | F8: =DataT7!G10 -> 292.72992 | G8: =DataT7!H10 -> 6.9248943 | H8: =DataT7!I10 -> 0.86376369 | ... L8: =DataT7!M10 -> -0.066310696
A9: =DataT7!B11 -> South & South-East Asia | B9: =DataT7!C11 -> 254.15353 | C9: =DataT7!D11 -> 1254.941 | D9: =DataT7!E11 -> 1939.319 | E9: =DataT7!F11 -> 2570.7754 | F9: =DataT7!G11 -> 2692.8218 | G9: =DataT7!H11 -> 10.595256 | H9: =DataT7!I11 -> 1.0545915 | ... L9: =DataT7!M11 -> 0.93195653
A10: =DataT7!B12 -> Sub-Saharan Africa | B10: =DataT7!C12 -> 99.95414 | C10: =DataT7!D12 -> 390.27625 | D10: =DataT7!E12 -> 681.90436 | E10: =DataT7!F12 -> 1170.1597 | F10: =DataT7!G12 -> 1324.0028 | G10: =DataT7!H12 -> 13.246103 | H10: =DataT7!I12 -> 1.1549311 | ... L10: =DataT7!M12 -> 2.5011549
A11: =DataT7!B13 -> World | B11: =DataT7!C13 -> 1007.0278 | C11: =DataT7!D13 -> 4447.1284 | D11: =DataT7!E13 -> 6170.9038 | E11: =DataT7!F13 -> 7885.9634 | F11: =DataT7!G13 -> 8230.5332 | G11: =DataT7!H13 -> 8.1730947 | H11: =DataT7!I13 -> 0.93808275 | ... L11: =DataT7!M13 -> 0.85899723
A12: Interpretation. Between 1800 and 2025, North America/Oceania and Latin America saw their populations grow more than 30-fold, while Europe, East Asia, and Russia/Central Asia experienced less than a 10-fold increase. Since 1980, Sub-Saharan Africa and the Middle East/North Africa have led in population growth rates (arround 3-fold), with Russia/Central Asia and Europe showing the slowest growth. Sources and series: wid.world

Sheet T8a
A1: =DataT8a!B3 -> Table 8a. Price index Growth PPP 2025 € by World Regions (1980-2025)
B2: =DataT8a!C4 -> 1800 Price index (PPP 2025 €) | C2: =DataT8a!D4 -> 1980 Price index (PPP 2025 €) | D2: =DataT8a!E4 -> 2000 Price index (PPP 2025 €) | E2: =DataT8a!F4 -> 2020 Price index (PPP 2025 €) | F2: =DataT8a!G4 -> 2025 Price index (PPP 2025 €) | G2: =DataT8a!H4 -> Annual growth rate 1800-2025 | H2: =DataT8a!I4 -> Annual growth rate 1980-2025 | I2: =DataT8a!J4 -> Annual growth rate 1980-2000 | J2: =DataT8a!K4 -> Annual growth rate 2000-2025
A3: =DataT8a!B5 -> East Asia | B3: =DataT8a!C5 -> 0.0015700549 | C3: =DataT8a!D5 -> 0.29674822 | D3: =DataT8a!E5 -> 0.57910627 | E3: =DataT8a!F5 -> 0.83524191 | F3: =DataT8a!G5 -> 1 | G3: =DataT8a!H5 -> 2.91119 | H3: =DataT8a!I5 -> 2.7364862 | ... J3: =DataT8a!K5 -> 2.2091248
A4: =DataT8a!B6 -> Europe | B4: =DataT8a!C6 -> 0.0017174565 | C4: =DataT8a!D6 -> 0.30642176 | D4: =DataT8a!E6 -> 0.6058858 | E4: =DataT8a!F6 -> 0.83755869 | F4: =DataT8a!G6 -> 1 | G4: =DataT8a!H6 -> 2.8701556 | H4: =DataT8a!I6 -> 2.6632764 | ... J4: =DataT8a!K6 -> 2.0244751
A5: =DataT8a!B7 -> Latin America | B5: =DataT8a!C7 -> 0.0016052589 | C5: =DataT8a!D7 -> 0.29722139 | D5: =DataT8a!E7 -> 0.60075706 | E5: =DataT8a!F7 -> 0.83682209 | F5: =DataT8a!G7 -> 1 | G5: =DataT8a!H7 -> 2.9010484 | H5: =DataT8a!I7 -> 2.7328489 | ... J5: =DataT8a!K7 -> 2.0591729
A6: =DataT8a!B8 -> MENA | B6: =DataT8a!C8 -> 0.00165345 | C6: =DataT8a!D8 -> 0.30088457 | D6: =DataT8a!E8 -> 0.61785024 | E6: =DataT8a!F8 -> 0.84192848 | F6: =DataT8a!G8 -> 1 | G6: =DataT8a!H8 -> 2.8875217 | H6: =DataT8a!I8 -> 2.7048879 | ... J6: =DataT8a!K8 -> 1.9447044
A7: =DataT8a!B9 -> North America & Oceania | B7: =DataT8a!C9 -> 0.0015868581 | C7: =DataT8a!D9 -> 0.30529642 | D7: =DataT8a!E9 -> 0.61371332 | E7: =DataT8a!F9 -> 0.83985311 | F7: =DataT8a!G9 -> 1 | G7: =DataT8a!H9 -> 2.9063213 | H7: =DataT8a!I9 -> 2.6716707 | ... J7: =DataT8a!K9 -> 1.9721035
A8: =DataT8a!B10 -> Russia & Central Asia | B8: =DataT8a!C10 -> 0.0018250472 | C8: =DataT8a!D10 -> 0.31163204 | D8: =DataT8a!E10 -> 0.6099689 | E8: =DataT8a!F10 -> 0.84124565 | F8: =DataT8a!G10 -> 1 | G8: =DataT8a!H10 -> 2.8423791 | H8: =DataT8a!I10 -> 2.6248176 | ... J8: =DataT8a!K10 -> 1.9970691
A9: =DataT8a!B11 -> South & South-East Asia | B9: =DataT8a!C11 -> 0.0015574421 | C9: =DataT8a!D11 -> 0.2986517 | D9: =DataT8a!E11 -> 0.59456915 | E9: =DataT8a!F11 -> 0.83105099 | F9: =DataT8a!G11 -> 1 | G9: =DataT8a!H11 -> 2.9148793 | H9: =DataT8a!I11 -> 2.7218897 | ... J9: =DataT8a!K11 -> 2.101449
A10: =DataT8a!B12 -> Sub-Saharan Africa | B10: =DataT8a!C12 -> 0.0019503632 | C10: =DataT8a!D12 -> 0.29437461 | D10: =DataT8a!E12 -> 0.49222594 | E10: =DataT8a!F12 -> 0.80471206 | F10: =DataT8a!G12 -> 1 | G10: =DataT8a!H12 -> 2.8120294 | H10: =DataT8a!I12 -> 2.7548227 | ... J10: =DataT8a!K12 -> 2.8758461
A11: =DataT8a!B13 -> World | B11: =DataT8a!C13 -> 0.0016282595 | C11: =DataT8a!D13 -> 0.28377786 | D11: =DataT8a!E13 -> 0.53426248 | E11: =DataT8a!F13 -> 0.82272089 | F11: =DataT8a!G13 -> 1 | G11: =DataT8a!H13 -> 2.8945422 | H11: =DataT8a!I13 -> 2.8385708 | ... J11: =DataT8a!K13 -> 2.5391736
A12: Interpretation. Between 1800 and 2025, the average inflation in PPP € at the global level has been 2.9% per year, accelating during the last decades: 3.5% per year over 1980-2000 and 4% over last 5 years (2020-2025). Sources and series: wid.world

Sheet T8b
A1: =DataT8b!B3 -> Table 8b. Price index Growth PPP 2025 $ by World Regions (1980-2025)
B2: =DataT8b!C4 -> 1800 Price index (PPP 2025 $) | C2: =DataT8b!D4 -> 1980 Price index (PPP 2025 $) | D2: =DataT8b!E4 -> 2000 Price index (PPP 2025 $) | E2: =DataT8b!F4 -> 2020 Price index (PPP 2025 $) | F2: =DataT8b!G4 -> 2025 Price index (PPP 2025 $) | G2: =DataT8b!H4 -> Annual growth rate 1800-2025 | H2: =DataT8b!I4 -> Annual growth rate 1980-2025 | I2: =DataT8b!J4 -> Annual growth rate 1980-2000 | ... K2: =DataT8b!L4 -> Annual growth rate 2020-2025
